Workbook

Sheet Perhitungan
A1: Obligasi | B1: FR0065 | C1: FR0068 | D1: FR0072
A2: Coupon | B2: 0.06625 | C2: 0.08375 | D2: 0.0825
A3: Periode Pemberian | B3: 2 | C3: 2 | D3: 2
A4: Yield Bid | B4: 0.0693 | C4: 0.0694 | D4: 0.0697
A5: Harga Beli | B5: 0.9835 | C5: 1.085 | D5: 1.091
A6: Dikeluarkan | B6: 41151 | C6: 41487 | D6: 42194
A7: Jatuh Tempo | B7: 48714 | C7: 49018 | D7: 49810
A8: Harga (FV) | B8: 1000000 | C8: 1000000 | D8: 1000000
A9: Sisa Tenor | B9: 7 | C9: 7.8 | D9: 10
A10: Harga (PV) | B10: =B8*B5 -> 983500 | C10: =C8*C5 -> 1085000 | D10: =D8*D5 -> 1091000
A11: YTM | B11: 0.0668 | C11: 0.0675 | D11: 0.0679
A14: FR0065 | F14: FR0068 | K14: FR0072
A15: Kupon p.a | B15: =B8*B2 -> 66250 | F15: Kupon p.a | G15: =C8*C2 -> 83750 | K15: Kupon p.a | L15: =D8*D2 -> 82500
A16: Kupon tiap periode | B16: =B15/2 -> 33125 | F16: Kupon tiap periode | G16: =G15/2 -> 41875 | K16: Kupon tiap periode | L16: =L15/2 -> 41250
A17: YTM periode | B17: =B11 -> 0.0668 | F17: YTM periode | G17: =C11 -> 0.0675 | K17: YTM periode | L17: =D11 -> 0.0679
A18: Sisa periode | B18: =B9 -> 7 | F18: Sisa periode | G18: =C9 -> 7.8 | K18: Sisa periode | L18: =D9 -> 10
A19: Jumlah Pembayaran | B19: =B18*2 -> 14 | F19: Jumlah Pembayaran | G19: =G18*2 -> 15.6 | K19: Jumlah Pembayaran | L19: =L18*2 -> 20
A22: Periode (t) | B22: Cash Flow | C22: PV | D22: Total | F22: Periode (t) | G22: Cash Flow | H22: PV | I22: Total | K22: Periode (t) | L22: Cash Flow | M22: PV | N22: Total
A23: 1 | B23: =$B$16 -> 33125 | C23: =B23/((1+$B$17)^A23) -> 31050.806 | D23: =A23*C23 -> 31050.806 | F23: 1 | G23: =$G$16 -> 41875 | H23: =G23/(1+$G$17)^F23 -> 39227.166 | I23: =F23*H23 -> 39227.166 | K23: 1 | L23: =$L$16 -> 41250 | M23: =L23/(1+$L$17)^K23 -> 38627.212 | N23: =K23*M23 -> 38627.212 | Q23: Rata Rata Tahunan | R23: =AVERAGE(D39,I41,N45) -> 5.7852054
A24: 2 | B24: =$B$16 -> 33125 | C24: =B24/((1+$B$17)^A24) -> 29106.492 | D24: =A24*C24 -> 58212.985 | F24: 2 | G24: =$G$16 -> 41875 | H24: =G24/(1+$G$17)^F24 -> 36746.76 | I24: =F24*H24 -> 73493.52 | K24: 2 | L24: =$L$16 -> 41250 | M24: =L24/(1+$L$17)^K24 -> 36171.189 | N24: =K24*M24 -> 72342.377
A25: 3 | B25: =$B$16 -> 33125 | C25: =B25/((1+$B$17)^A25) -> 27283.926 | D25: =A25*C25 -> 81851.779 | F25: 3 | G25: =$G$16 -> 41875 | H25: =G25/(1+$G$17)^F25 -> 34423.194 | I25: =F25*H25 -> 103269.58 | K25: 3 | L25: =$L$16 -> 41250 | M25: =L25/(1+$L$17)^K25 -> 33871.326 | N25: =K25*M25 -> 101613.98
A26: 4 | B26: =$B$16 -> 33125 | C26: =B26/((1+$B$17)^A26) -> 25575.484 | D26: =A26*C26 -> 102301.94 | F26: 4 | G26: =$G$16 -> 41875 | H26: =G26/(1+$G$17)^F26 -> 32246.552 | I26: =F26*H26 -> 128986.21 | K26: 4 | L26: =$L$16 -> 41250 | M26: =L26/(1+$L$17)^K26 -> 31717.694 | N26: =K26*M26 -> 126870.78
A27: 5 | B27: =$B$16 -> 33125 | C27: =B27/((1+$B$17)^A27) -> 23974.019 | D27: =A27*C27 -> 119870.1 | F27: 5 | G27: =$G$16 -> 41875 | H27: =G27/(1+$G$17)^F27 -> 30207.543 | I27: =F27*H27 -> 151037.71 | K27: 5 | L27: =$L$16 -> 41250 | M27: =L27/(1+$L$17)^K27 -> 29700.996 | N27: =K27*M27 -> 148504.98
A28: 6 | B28: =$B$16 -> 33125 | C28: =B28/((1+$B$17)^A28) -> 22472.834 | D28: =A28*C28 -> 134837 | F28: 6 | G28: =$G$16 -> 41875 | H28: =G28/(1+$G$17)^F28 -> 28297.464 | I28: =F28*H28 -> 169784.78 | K28: 6 | L28: =$L$16 -> 41250 | M28: =L28/(1+$L$17)^K28 -> 27812.526 | N28: =K28*M28 -> 166875.16
A29: 7 | B29: =$B$16 -> 33125 | C29: =B29/((1+$B$17)^A29) -> 21065.649 | D29: =A29*C29 -> 147459.54 | F29: 7 | G29: =$G$16 -> 41875 | H29: =G29/(1+$G$17)^F29 -> 26508.163 | I29: =F29*H29 -> 185557.14 | K29: 7 | L29: =$L$16 -> 41250 | M29: =L29/(1+$L$17)^K29 -> 26044.13 | N29: =K29*M29 -> 182308.91
A30: 8 | B30: =$B$16 -> 33125 | C30: =B30/((1+$B$17)^A30) -> 19746.577 | D30: =A30*C30 -> 157972.62 | F30: 8 | G30: =$G$16 -> 41875 | H30: =G30/(1+$G$17)^F30 -> 24832.003 | I30: =F30*H30 -> 198656.02 | K30: 8 | L30: =$L$16 -> 41250 | M30: =L30/(1+$L$17)^K30 -> 24388.173 | N30: =K30*M30 -> 195105.38
A31: 9 | B31: =$B$16 -> 33125 | C31: =B31/((1+$B$17)^A31) -> 18510.103 | D31: =A31*C31 -> 166590.92 | F31: 9 | G31: =$G$16 -> 41875 | H31: =G31/(1+$G$17)^F31 -> 23261.829 | I31: =F31*H31 -> 209356.46 | K31: 9 | L31: =$L$16 -> 41250 | M31: =L31/(1+$L$17)^K31 -> 22837.506 | N31: =K31*M31 -> 205537.55
A32: 10 | B32: =$B$16 -> 33125 | C32: =B32/((1+$B$17)^A32) -> 17351.052 | D32: =A32*C32 -> 173510.52 | F32: 10 | G32: =$G$16 -> 41875 | H32: =G32/(1+$G$17)^F32 -> 21790.941 | I32: =F32*H32 -> 217909.41 | K32: 10 | L32: =$L$16 -> 41250 | M32: =L32/(1+$L$17)^K32 -> 21385.435 | N32: =K32*M32 -> 213854.35
A33: 11 | B33: =$B$16 -> 33125 | C33: =B33/((1+$B$17)^A33) -> 16264.578 | D33: =A33*C33 -> 178910.36 | F33: 11 | G33: =$G$16 -> 41875 | H33: =G33/(1+$G$17)^F33 -> 20413.059 | I33: =F33*H33 -> 224543.65 | K33: 11 | L33: =$L$16 -> 41250 | M33: =L33/(1+$L$17)^K33 -> 20025.691 | N33: =K33*M33 -> 220282.6
A34: 12 | B34: =$B$16 -> 33125 | C34: =B34/((1+$B$17)^A34) -> 15246.136 | D34: =A34*C34 -> 182953.64 | F34: 12 | G34: =$G$16 -> 41875 | H34: =G34/(1+$G$17)^F34 -> 19122.304 | I34: =F34*H34 -> 229467.65 | K34: 12 | L34: =$L$16 -> 41250 | M34: =L34/(1+$L$17)^K34 -> 18752.402 | N34: =K34*M34 -> 225028.83
A35: 13 | B35: =$B$16 -> 33125 | C35: =B35/((1+$B$17)^A35) -> 14291.467 | D35: =A35*C35 -> 185789.06 | F35: 13 | G35: =$G$16 -> 41875 | H35: =G35/(1+$G$17)^F35 -> 17913.165 | I35: =F35*H35 -> 232871.15 | K35: 13 | L35: =$L$16 -> 41250 | M35: =L35/(1+$L$17)^K35 -> 17560.073 | N35: =K35*M35 -> 228280.95
A36: 14 | B36: =$B$16+B8 -> 1033125 | C36: =B36/((1+$B$17)^A36) -> 417821.49 | D36: =A36*C36 -> 5849500.8 | F36: 14 | G36: =$G$16 -> 41875 | H36: =G36/(1+$G$17)^F36 -> 16780.483 | I36: =F36*H36 -> 234926.76 | K36: 14 | L36: =$L$16 -> 41250 | M36: =L36/(1+$L$17)^K36 -> 16443.556 | N36: =K36*M36 -> 230209.78
C37: =SUM(C23:C36) -> 699760.61 | D37: =SUM(D23:D36) -> 7570812.1 | F37: 15 | G37: =$G$16 -> 41875 | H37: =G37/(1+$G$17)^F37 -> 15719.422 | I37: =F37*H37 -> 235791.33 | K37: 15 | L37: =$L$16 -> 41250 | M37: =L37/(1+$L$17)^K37 -> 15398.03 | N37: =K37*M37 -> 230970.45
C38: Durasi | D38: =D37/C37 -> 10.819146 | F38: 15.6 | G38: =$G$16+C8 -> 1041875 | H38: =G38/(1+$G$17)^F38 -> 376076.88 | I38: =F38*H38 -> 5866799.3 | K38: 16 | L38: =$L$16 -> 41250 | M38: =L38/(1+$L$17)^K38 -> 14418.981 | N38: =K38*M38 -> 230703.7
D39: =D38/2 -> 5.4095729 | H39: =SUM(H23:H38) -> 763566.93 | I39: =SUM(I23:I38) -> 8501677.8 | K39: 17 | L39: =$L$16 -> 41250 | M39: =L39/(1+$L$17)^K39 -> 13502.183 | N39: =K39*M39 -> 229537.11
I40: =I39/H39 -> 11.134162 | K40: 18 | L40: =$L$16 -> 41250 | M40: =L40/(1+$L$17)^K40 -> 12643.677 | N40: =K40*M40 -> 227586.19
I41: =I40/2 -> 5.567081 | K41: 19 | L41: =$L$16 -> 41250 | M41: =L41/(1+$L$17)^K41 -> 11839.758 | N41: =K41*M41 -> 224955.39
K42: 20 | L42: =$L$16+D8 -> 1041250 | M42: =L42/(1+$L$17)^K42 -> 279861.58 | N42: =K42*M42 -> 5597231.6
M43: =SUM(M23:M42) -> 713002.12 | N43: =SUM(N23:N42) -> 9096427.3
N44: =N43/M43 -> 12.757925
...

Sheet Simulasi Obligasi
A1: Obligasi | B1: FR0064 | C1: FR0072 | D1: FR0097 | E1: FR00102
A2: Coupon | B2: 0.06125 | C2: 0.0825 | D2: 0.07125 | E2: 0.07375
A3: Periode Pemberian | B3: 2 | C3: 2 | D3: 2 | E3: 2
A4: Yield Bid | B4: 0.0711 | C4: 0.0697 | D4: 0.0697 | E4: 0.0706
A5: Harga Beli | B5: 0.982 | C5: 1.091 | D5: 1.021 | E5: 0.9775
A6: Dikeluarkan | B6: 41134 | C6: 42194 | D6: 44792 | E6: 45296
A7: Jatuh Tempo | B7: 46888 | C7: 49810 | D7: 52397 | E7: 56445
A8: Harga (FV) | B8: 1000000 | C8: 1000000 | D8: 1000000 | E8: 1000000
A9: Sisa Tenor | B9: 2 | C9: 10 | D9: 17.1 | E9: 28.2
A10: Harga (PV) | B10: =B8*B5 -> 982000 | C10: =C8*C5 -> 1091000 | D10: 1021000 | E10: 977500
A11: YTM | B11: 0.0626 | C11: 0.0679 | D11: 0.0691 | E11: 0.0692
A14: FR0065 | G14: FR0072 | M14: FR0097 | S14: FR00102
A15: Kupon p.a | B15: =B2*B8 -> 61250 | G15: Kupon p.a | H15: =C8*C2 -> 82500 | M15: Kupon p.a | N15: =D2*D8 -> 71250 | S15: Kupon p.a | T15: =E2*E8 -> 73750
A16: Kupon tiap periode | B16: =B15/2 -> 30625 | G16: Kupon tiap periode | H16: =H15/2 -> 41250 | M16: Kupon tiap periode | N16: =N15/2 -> 35625 | S16: Kupon tiap periode | T16: =T15/2 -> 36875
A17: YTM periode | B17: =B11 -> 0.0626 | G17: YTM periode | H17: =C11 -> 0.0679 | M17: YTM periode | N17: =D11 -> 0.0691 | S17: YTM periode | T17: =E11 -> 0.0692
A18: Sisa periode | B18: =B9 -> 2 | G18: Sisa periode | H18: =C9 -> 10 | M18: Sisa periode | N18: =D9 -> 17.1 | S18: Sisa periode | T18: =E9 -> 28.2
A19: Jumlah Pembayaran | B19: =B18*2 -> 4 | G19: Jumlah Pembayaran | H19: =H18*2 -> 20 | M19: Jumlah Pembayaran | N19: =N18*2 -> 34.2 | S19: Jumlah Pembayaran | T19: =T18*2 -> 56.4
A22: Periode (t) | B22: Cash Flow | C22: PV | D22: Total | G22: Periode (t) | H22: Cash Flow | I22: PV | J22: Total | M22: Periode (t) | N22: Cash Flow | O22: PV | P22: Total | S22: Periode (t) | T22: Cash Flow | U22: PV | V22: Total
A23: 1 | B23: =$B$16 -> 30625 | C23: =B23/((1+$B$17)^A23) -> 28820.817 | D23: =A23*C23 -> 28820.817 | G23: 1 | H23: =$H$16 -> 41250 | I23: =H23/(1+$H$17)^G23 -> 38627.212 | J23: =G23*I23 -> 38627.212 | M23: 1 | N23: =N16 -> 35625 | O23: =N23/(1+$N$17)^M23 -> 33322.421 | P23: =O23*M23 -> 33322.421 | S23: 1 | T23: =T16 -> 36875 | U23: =T23/(1+$T$17)^S23 -> 34488.403 | V23: =U23*S23 -> 34488.403
A24: 2 | B24: =$B$16 -> 30625 | C24: =B24/((1+$B$17)^A24) -> 27122.922 | D24: =A24*C24 -> 54245.844 | G24: 2 | H24: =$H$16 -> 41250 | I24: =H24/(1+$H$17)^G24 -> 36171.189 | J24: =G24*I24 -> 72342.377 | M24: 2 | N24: =$N$23 -> 35625 | O24: =N24/(1+$N$17)^M24 -> 31168.666 | P24: =O24*M24 -> 62337.332 | S24: 2 | T24: =$T$23 -> 36875 | U24: =T24/(1+$T$17)^S24 -> 32256.269 | V24: =U24*S24 -> 64512.537
A25: 3 | B25: =$B$16 -> 30625 | C25: =B25/((1+$B$17)^A25) -> 25525.054 | D25: =A25*C25 -> 76575.161 | G25: 3 | H25: =$H$16 -> 41250 | I25: =H25/(1+$H$17)^G25 -> 33871.326 | J25: =G25*I25 -> 101613.98 | M25: 3 | N25: =$N$23 -> 35625 | O25: =N25/(1+$N$17)^M25 -> 29154.116 | P25: =O25*M25 -> 87462.349 | S25: 3 | T25: =$T$23 -> 36875 | U25: =T25/(1+$T$17)^S25 -> 30168.602 | V25: =U25*S25 -> 90505.805
A26: 4 | B26: =$B$16+B8 -> 1030625 | C26: =B26/((1+$B$17)^A26) -> 808390.92 | D26: =A26*C26 -> 3233563.7 | G26: 4 | H26: =$H$16 -> 41250 | I26: =H26/(1+$H$17)^G26 -> 31717.694 | J26: =G26*I26 -> 126870.78 | M26: 4 | N26: =$N$23 -> 35625 | O26: =N26/(1+$N$17)^M26 -> 27269.775 | P26: =O26*M26 -> 109079.1 | S26: 4 | T26: =$T$23 -> 36875 | U26: =T26/(1+$T$17)^S26 -> 28216.051 | V26: =U26*S26 -> 112864.2
C27: =SUM(C23:C26) -> 889859.71 | D27: =SUM(D23:D26) -> 3393205.5 | G27: 5 | H27: =$H$16 -> 41250 | I27: =H27/(1+$H$17)^G27 -> 29700.996 | J27: =G27*I27 -> 148504.98 | M27: 5 | N27: =$N$23 -> 35625 | O27: =N27/(1+$N$17)^M27 -> 25507.226 | P27: =O27*M27 -> 127536.13 | S27: 5 | T27: =$T$23 -> 36875 | U27: =T27/(1+$T$17)^S27 -> 26389.872 | V27: =U27*S27 -> 131949.36
C28: Durasi | D28: =D27/C27 -> 3.8131915 | G28: 6 | H28: =$H$16 -> 41250 | I28: =H28/(1+$H$17)^G28 -> 27812.526 | J28: =G28*I28 -> 166875.16 | M28: 6 | N28: =$N$23 -> 35625 | O28: =N28/(1+$N$17)^M28 -> 23858.597 | P28: =O28*M28 -> 143151.58 | S28: 6 | T28: =$T$23 -> 36875 | U28: =T28/(1+$T$17)^S28 -> 24681.885 | V28: =U28*S28 -> 148091.31
D29: =D28/2 -> 1.9065958 | G29: 7 | H29: =$H$16 -> 41250 | I29: =H29/(1+$H$17)^G29 -> 26044.13 | J29: =G29*I29 -> 182308.91 | M29: 7 | N29: =$N$23 -> 35625 | O29: =N29/(1+$N$17)^M29 -> 22316.525 | P29: =O29*M29 -> 156215.67 | S29: 7 | T29: =$T$23 -> 36875 | U29: =T29/(1+$T$17)^S29 -> 23084.442 | V29: =U29*S29 -> 161591.09
G30: 8 | H30: =$H$16 -> 41250 | I30: =H30/(1+$H$17)^G30 -> 24388.173 | J30: =G30*I30 -> 195105.38 | M30: 8 | N30: =$N$23 -> 35625 | O30: =N30/(1+$N$17)^M30 -> 20874.123 | P30: =O30*M30 -> 166992.98 | S30: 8 | T30: =$T$23 -> 36875 | U30: =T30/(1+$T$17)^S30 -> 21590.387 | V30: =U30*S30 -> 172723.1
A31: Durasi | G31: 9 | H31: =$H$16 -> 41250 | I31: =H31/(1+$H$17)^G31 -> 22837.506 | J31: =G31*I31 -> 205537.55 | M31: 9 | N31: =$N$23 -> 35625 | O31: =N31/(1+$N$17)^M31 -> 19524.949 | P31: =O31*M31 -> 175724.54 | S31: 9 | T31: =$T$23 -> 36875 | U31: =T31/(1+$T$17)^S31 -> 20193.029 | V31: =U31*S31 -> 181737.26
A32: FR0064 | B32: =D29 -> 1.9065958 | G32: 10 | H32: =$H$16 -> 41250 | I32: =H32/(1+$H$17)^G32 -> 21385.435 | J32: =G32*I32 -> 213854.35 | M32: 10 | N32: =$N$23 -> 35625 | O32: =N32/(1+$N$17)^M32 -> 18262.977 | P32: =O32*M32 -> 182629.77 | S32: 10 | T32: =$T$23 -> 36875 | U32: =T32/(1+$T$17)^S32 -> 18886.111 | V32: =U32*S32 -> 188861.11
A33: FR0072 | B33: =J45 -> 6.3789623 | G33: 11 | H33: =$H$16 -> 41250 | I33: =H33/(1+$H$17)^G33 -> 20025.691 | J33: =G33*I33 -> 220282.6 | M33: 11 | N33: =$N$23 -> 35625 | O33: =N33/(1+$N$17)^M33 -> 17082.572 | P33: =O33*M33 -> 187908.29 | S33: 11 | T33: =$T$23 -> 36875 | U33: =T33/(1+$T$17)^S33 -> 17663.777 | V33: =U33*S33 -> 194301.55
A34: FR0097 | B34: =P60 -> 7.8820166 | G34: 12 | H34: =$H$16 -> 41250 | I34: =H34/(1+$H$17)^G34 -> 18752.402 | J34: =G34*I34 -> 225028.83 | M34: 12 | N34: =$N$23 -> 35625 | O34: =N34/(1+$N$17)^M34 -> 15978.46 | P34: =O34*M34 -> 191741.52 | S34: 12 | T34: =$T$23 -> 36875 | U34: =T34/(1+$T$17)^S34 -> 16520.555 | V34: =U34*S34 -> 198246.66
A35: FR00102 | B35: =V80 -> 7.9859271 | G35: 13 | H35: =$H$16 -> 41250 | I35: =H35/(1+$H$17)^G35 -> 17560.073 | J35: =G35*I35 -> 228280.95 | M35: 13 | N35: =$N$23 -> 35625 | O35: =N35/(1+$N$17)^M35 -> 14945.711 | P35: =O35*M35 -> 194294.25 | S35: 13 | T35: =$T$23 -> 36875 | U35: =T35/(1+$T$17)^S35 -> 15451.323 | V35: =U35*S35 -> 200867.2
G36: 14 | H36: =$H$16 -> 41250 | I36: =H36/(1+$H$17)^G36 -> 16443.556 | J36: =G36*I36 -> 230209.78 | M36: 14 | N36: =$N$23 -> 35625 | O36: =N36/(1+$N$17)^M36 -> 13979.713 | P36: =O36*M36 -> 195715.98 | S36: 14 | T36: =$T$23 -> 36875 | U36: =T36/(1+$T$17)^S36 -> 14451.294 | V36: =U36*S36 -> 202318.11
G37: 15 | H37: =$H$16 -> 41250 | I37: =H37/(1+$H$17)^G37 -> 15398.03 | J37: =G37*I37 -> 230970.45 | M37: 15 | N37: =$N$23 -> 35625 | O37: =N37/(1+$N$17)^M37 -> 13076.151 | P37: =O37*M37 -> 196142.27 | S37: 15 | T37: =$T$23 -> 36875 | U37: =T37/(1+$T$17)^S37 -> 13515.987 | V37: =U37*S37 -> 202739.81
G38: 16 | H38: =$H$16 -> 41250 | I38: =H38/(1+$H$17)^G38 -> 14418.981 | J38: =G38*I38 -> 230703.7 | M38: 16 | N38: =$N$23 -> 35625 | O38: =N38/(1+$N$17)^M38 -> 12230.99 | P38: =O38*M38 -> 195695.84 | S38: 16 | T38: =$T$23 -> 36875 | U38: =T38/(1+$T$17)^S38 -> 12641.215 | V38: =U38*S38 -> 202259.44
G39: 17 | H39: =$H$16 -> 41250 | I39: =H39/(1+$H$17)^G39 -> 13502.183 | J39: =G39*I39 -> 229537.11 | M39: 17 | N39: =$N$23 -> 35625 | O39: =N39/(1+$N$17)^M39 -> 11440.454 | P39: =O39*M39 -> 194487.72 | S39: 17 | T39: =$T$23 -> 36875 | U39: =T39/(1+$T$17)^S39 -> 11823.06 | V39: =U39*S39 -> 200992.01
G40: 18 | H40: =$H$16 -> 41250 | I40: =H40/(1+$H$17)^G40 -> 12643.677 | J40: =G40*I40 -> 227586.19 | M40: 18 | N40: =$N$23 -> 35625 | O40: =N40/(1+$N$17)^M40 -> 10701.014 | P40: =O40*M40 -> 192618.26 | S40: 18 | T40: =$T$23 -> 36875 | U40: =T40/(1+$T$17)^S40 -> 11057.856 | V40: =U40*S40 -> 199041.41
G41: 19 | H41: =$H$16 -> 41250 | I41: =H41/(1+$H$17)^G41 -> 11839.758 | J41: =G41*I41 -> 224955.39 | M41: 19 | N41: =$N$23 -> 35625 | O41: =N41/(1+$N$17)^M41 -> 10009.367 | P41: =O41*M41 -> 190177.97 | S41: 19 | T41: =$T$23 -> 36875 | U41: =T41/(1+$T$17)^S41 -> 10342.177 | V41: =U41*S41 -> 196501.37
G42: 20 | H42: =$H$16+C8 -> 1041250 | I42: =H42/(1+$H$17)^G42 -> 279861.58 | J42: =G42*I42 -> 5597231.6 | M42: 20 | N42: =$N$23 -> 35625 | O42: =N42/(1+$N$17)^M42 -> 9362.4235 | P42: =O42*M42 -> 187248.47 | S42: 20 | T42: =$T$23 -> 36875 | U42: =T42/(1+$T$17)^S42 -> 9672.8182 | V42: =U42*S42 -> 193456.36
I43: =SUM(I23:I42) -> 713002.12 | J43: =SUM(J23:J42) -> 9096427.3 | M43: 21 | N43: =$N$23 -> 35625 | O43: =N43/(1+$N$17)^M43 -> 8757.2945 | P43: =O43*M43 -> 183903.18 | S43: 21 | T43: =$T$23 -> 36875 | U43: =T43/(1+$T$17)^S43 -> 9046.781 | V43: =U43*S43 -> 189982.4
I44: Durasi | J44: =J43/I43 -> 12.757925 | M44: 22 | N44: =$N$23 -> 35625 | O44: =N44/(1+$N$17)^M44 -> 8191.2772 | P44: =O44*M44 -> 180208.1 | S44: 22 | T44: =$T$23 -> 36875 | U44: =T44/(1+$T$17)^S44 -> 8461.2617 | V44: =U44*S44 -> 186147.76
...

Sheet VaR
A1: tanggal | B1: FR0064 | D1: FR0072 | F1: FR0097 | H1: FR00102 | X1: 0.05 | AB1: Return
B2: harga_beli | C2: harga_jual | D2: harga_beli | E2: harga_jual | F2: harga_beli | G2: harga_jual | H2: harga_beli | I2: harga_jual | X2: 100000000 | AB2: 1 | AC2: 2 | AD2: 3 | AE2: 4 | AF2: 5 | AG2: 6
A3: 45299 | B3: 99 | C3: 97.8 | D3: 113.3 | E3: 112.1 | F3: 102.8 | G3: 101.65 | H3: 99.55 | I3: 98.4 | K3: FR0064 | L3: FR0072 | M3: FR0097 | N3: FR00102 | AB3: =K4*$S$108+L4*$T$108 -> -0.0031851352 | AC3: =K4*$S$109+M4*$T$109 -> 0.0018263158 | AD3: =K4*$S$110+N4*$T$110 -> 0.00058643986 | AE3: =L4*$S$111+M4*$T$111 -> -0.0012854921 | AF3: =L4*$S$112+N4*$T$112 -> -0.0019990945 | AG3: =M4*$S$113+N4*$T$113 -> 0.0018531647
A4: 45300 | B4: 99 | C4: 97.9 | D4: 113.2 | E4: 111.7 | F4: 102.85 | G4: 101.85 | H4: 99.6 | I4: 98.5 | K4: =LN(C4/C3) -> 0.0010219725 | L4: =LN(E4/E3) -> -0.003574624 | M4: =LN(G4/G3) -> 0.0019656026 | N4: =LN(H4/H3) -> 0.00050213408 | AB4: =K5*$S$108+L5*$T$108 -> 0.0017238351 | AC4: =K5*$S$109+M5*$T$109 -> -0.00026786087 | AD4: =K5*$S$110+N5*$T$110 -> -0.00025512842 | AE4: =L5*$S$111+M5*$T$111 -> 0.00084687174 | AF4: =L5*$S$112+N5*$T$112 -> 0.00090349826 | AG4: =M5*$S$113+N5*$T$113 -> -0.00049189102
A5: 45301 | B5: 99.1 | C5: 98 | D5: 113.2 | E5: 111.9 | F5: 103 | G5: 101.8 | H5: 99.55 | I5: 98.6 | K5: =LN(C5/C4) -> 0.0010209291 | L5: =LN(E5/E4) -> 0.0017889092 | M5: =LN(G5/G4) -> -0.00049103856 | N5: =LN(H5/H4) -> -0.00050213408 | AB5: =K6*$S$108+L6*$T$108 -> 0.00021588338 | AC5: =K6*$S$109+M6*$T$109 -> 0.0020490688 | AD5: =K6*$S$110+N6*$T$110 -> 0.0037728859 | AE5: =L6*$S$111+M6*$T$111 -> 0.00081095964 | AF5: =L6*$S$112+N6*$T$112 -> 0.0015497415 | AG5: =M6*$S$113+N6*$T$113 -> 0.0021200043
A6: 45302 | B6: 99.4 | C6: 98.25 | D6: 113.1 | E6: 111.9 | F6: 103 | G6: 102 | H6: 99.95 | I6: 98.8 | K6: =LN(C6/C5) -> 0.0025477721 | L6: =LN(E6/E5) -> 0 | M6: =LN(G6/G5) -> 0.0019627092 | N6: =LN(H6/H5) -> 0.0040100304 | AB6: =K7*$S$108+L7*$T$108 -> 0 | AC6: =K7*$S$109+M7*$T$109 -> 0.0020866413 | AD6: =K7*$S$110+N7*$T$110 -> -0.00041922598 | AE6: =L7*$S$111+M7*$T$111 -> 0.0010114664 | AF6: =L7*$S$112+N7*$T$112 -> -0.00019337818 | AG6: =M7*$S$113+N7*$T$113 -> 0.0022214603
A7: 45303 | B7: 99.35 | C7: 98.25 | D7: 113.2 | E7: 111.9 | F7: 103.25 | G7: 102.25 | H7: 99.9 | I7: 98.7 | K7: =LN(C7/C6) -> 0 | L7: =LN(E7/E6) -> 0 | M7: =LN(G7/G6) -> 0.0024479816 | N7: =LN(H7/H6) -> -0.00050037529 | AB7: =K8*$S$108+L8*$T$108 -> 0.0026658471 | AC7: =K8*$S$109+M8*$T$109 -> 0.00037511442 | AD7: =K8*$S$110+N8*$T$110 -> 0.00041213972 | AE7: =L8*$S$111+M8*$T$111 -> 0.0015711286 | AF7: =L8*$S$112+N8*$T$112 -> 0.0016426616 | AG7: =M8*$S$113+N8*$T$113 -> 0
A8: 45306 | B8: 99.5 | C8: 98.5 | D8: 113.4 | E8: 112.2 | F8: 103.3 | G8: 102.25 | H8: 99.9 | I8: 98.95 | K8: =LN(C8/C7) -> 0.0025412974 | L8: =LN(E8/E7) -> 0.0026773778 | M8: =LN(G8/G7) -> 0 | N8: =LN(H8/H7) -> 0 | AB8: =K9*$S$108+L9*$T$108 -> -0.00090217692 | AC8: =K9*$S$109+M9*$T$109 -> -0.0022365727 | AD8: =K9*$S$110+N9*$T$110 -> -0.001843735 | AE8: =L9*$S$111+M9*$T$111 -> -0.0015347087 | AF8: =L9*$S$112+N9*$T$112 -> -0.0013215471 | AG8: =M9*$S$113+N9*$T$113 -> -0.0024138713
A9: 45307 | B9: 99.5 | C9: 98.4 | D9: 113.3 | E9: 112.1 | F9: 103.2 | G9: 102 | H9: 99.7 | I9: 98.5 | K9: =LN(C9/C8) -> -0.0010157441 | L9: =LN(E9/E8) -> -0.00089166301 | M9: =LN(G9/G8) -> -0.0024479816 | N9: =LN(H9/H8) -> -0.0020040087 | AB9: =K10*$S$108+L10*$T$108 -> 8.6068247e-05 | AC9: =K10*$S$109+M10*$T$109 -> 0.00098520099 | AD9: =K10*$S$110+N10*$T$110 -> 0.00016473022 | AE9: =L10*$S$111+M10*$T$111 -> 0.00040488372 | AF9: =L10*$S$112+N10*$T$112 -> 0 | AG9: =M10*$S$113+N10*$T$113 -> 0.00090462555
A10: 45308 | B10: 99.6 | C10: 98.5 | D10: 113.3 | E10: 112.1 | F10: 103.3 | G10: 102.1 | H10: 99.7 | I10: 98.7 | K10: =LN(C10/C9) -> 0.0010157441 | L10: =LN(E10/E9) -> 0 | M10: =LN(G10/G9) -> 0.00097991189 | N10: =LN(H10/H9) -> 0 | AB10: =K11*$S$108+L11*$T$108 -> -0.0011184591 | AC10: =K11*$S$109+M11*$T$109 -> -0.00052542751 | AD10: =K11*$S$110+N11*$T$110 -> 0.0011017155 | AE10: =L11*$S$111+M11*$T$111 -> -0.00052370927 | AF10: =L11*$S$112+N11*$T$112 -> 0.00022692821 | AG10: =M11*$S$113+N11*$T$113 -> 0.00015396739
A11: 45309 | B11: 99.35 | C11: 98.15 | D11: 113.3 | E11: 112 | F11: 103.15 | G11: 102.1 | H11: 99.9 | I11: 98.7 | K11: =LN(C11/C10) -> -0.0035596275 | L11: =LN(E11/E10) -> -0.00089245878 | M11: =LN(G11/G10) -> 0 | N11: =LN(H11/H10) -> 0.0020040087 | AB11: =K12*$S$108+L12*$T$108 -> -0.00012971564 | AC11: =K12*$S$109+M12*$T$109 -> 0.0036991496 | AD11: =K12*$S$110+N12*$T$110 -> 0.00047742988 | AE11: =L12*$S$111+M12*$T$111 -> 0.00068809901 | AF11: =L12*$S$112+N12*$T$112 -> -0.00093508954 | AG11: =M12*$S$113+N12*$T$113 -> 0.0026316249
A12: 45310 | B12: 99.8 | C12: 98.95 | D12: 113.2 | E12: 111.9 | F12: 103.4 | G12: 102.4 | H12: 99.8 | I12: 99.15 | K12: =LN(C12/C11) -> 0.0081177513 | L12: =LN(E12/E11) -> -0.00089325598 | M12: =LN(G12/G11) -> 0.0029339874 | N12: =LN(H12/H11) -> -0.0010015023 | AB12: =K13*$S$108+L13*$T$108 -> 0.0021502644 | AC12: =K13*$S$109+M13*$T$109 -> 0.0015554666 | AD12: =K13*$S$110+N13*$T$110 -> 0.0011026648 | AE12: =L13*$S$111+M13*$T$111 -> 0.0025786488 | AF12: =L13*$S$112+N13*$T$112 -> 0.0024163681 | AG12: =M13*$S$113+N13*$T$113 -> 0.0024049002
A13: 45313 | B13: 99.8 | C13: 98.6 | D13: 113.4 | E13: 112.2 | F13: 103.6 | G13: 102.65 | H13: 100 | I13: 98.8 | K13: =LN(C13/C12) -> -0.0035434104 | L13: =LN(E13/E12) -> 0.0026773778 | M13: =LN(G13/G12) -> 0.0024384309 | N13: =LN(H13/H12) -> 0.0020020027 | AB13: =K14*$S$108+L14*$T$108 -> 0.00098708216 | AC13: =K14*$S$109+M14*$T$109 -> -0.00094738857 | AD13: =K14*$S$110+N14*$T$110 -> -0.00050961626 | AE13: =L14*$S$111+M14*$T$111 -> -8.1441063e-05 | AF13: =L14*$S$112+N14*$T$112 -> 0.00015991833 | AG13: =M14*$S$113+N14*$T$113 -> -0.0014268615
A14: 45314 | B14: 99.9 | C14: 98.8 | D14: 113.3 | E14: 112.3 | F14: 103.55 | G14: 102.5 | H14: 99.9 | I14: 99.2 | K14: =LN(C14/C13) -> 0.0020263431 | L14: =LN(E14/E13) -> 0.00089086866 | M14: =LN(G14/G13) -> -0.0014623449 | N14: =LN(H14/H13) -> -0.0010005003 | AB14: =K15*$S$108+L15*$T$108 -> -0.0013091518 | AC14: =K15*$S$109+M15*$T$109 -> -0.005572104 | AD14: =K15*$S$110+N15*$T$110 -> 0.00067401252 | AE14: =L15*$S$111+M15*$T$111 -> -0.0034128722 | AF14: =L15*$S$112+N15*$T$112 -> -0.00043339001 | AG14: =M15*$S$113+N15*$T$113 -> -0.0057960236
A15: 45315 | B15: 99.8 | C15: 98.7 | D15: 113.35 | E15: 112.15 | F15: 102.95 | G15: 101.85 | H15: 100 | I15: 98.9 | K15: =LN(C15/C14) -> -0.0010126583 | L15: =LN(E15/E14) -> -0.0013366008 | M15: =LN(G15/G14) -> -0.0063616559 | N15: =LN(H15/H14) -> 0.0010005003 | AB15: =K16*$S$108+L16*$T$108 -> -0.0016766104 | AC15: =K16*$S$109+M16*$T$109 -> -0.0021696411 | AD15: =K16*$S$110+N16*$T$110 -> -0.0009204196 | AE15: =L16*$S$111+M16*$T$111 -> -0.0020628624 | AF15: =L16*$S$112+N16*$T$112 -> -0.001481767 | AG15: =M16*$S$113+N16*$T$113 -> -0.0023456584
... A97: 45429 | B97: 98.25 | C97: 97.25 | D97: 111.55 | E97: 110.35 | F97: 102.7 | G97: 101.5 | H97: 100.2 | I97: 98.9 | K97: =LN(C97/C96) -> 0.0015436072 | L97: =LN(E97/E96) -> 0.0072760667 | M97: =LN(G97/G96) -> -0.00049248954 | N97: =LN(H97/H96) -> 0 | AB97: =K98*$S$108+L98*$T$108 -> -0.0010042368 | AC97: =K98*$S$109+M98*$T$109 -> -0.0024059543 | AD97: =K98*$S$110+N98*$T$110 -> -0.0024268583 | AE97: =L98*$S$111+M98*$T$111 -> -0.0015509678 | AF97: =L98*$S$112+N98*$T$112 -> -0.0015216831 | AG97: =M98*$S$113+N98*$T$113 -> -0.0024685538
A98: 45432 | B98: 98.15 | C98: 97.05 | D98: 111.35 | E98: 110.25 | F98: 102.35 | G98: 101.25 | H98: 99.95 | I98: 98.85 | K98: =LN(C98/C97) -> -0.0020586729 | L98: =LN(E98/E97) -> -0.00090661838 | M98: =LN(G98/G97) -> -0.0024660925 | N98: =LN(H98/H97) -> -0.0024981277 | R98: FR0064 | S98: FR0072 | T98: FR0097 | U98: FR00102 | X98: {=TRANSPOSE(R103:T103)} -> -1.6448536 | AB98: =K99*$S$108+L99*$T$108 -> -0.0033267309 | AC98: =K99*$S$109+M99*$T$109 -> -0.0016854035 | AD98: =K99*$S$110+N99*$T$110 -> -0.0037806071 | AE98: =L99*$S$111+M99*$T$111 -> -0.0029498826 | AF98: =L99*$S$112+N99*$T$112 -> -0.0039739174 | AG98: =M99*$S$113+N99*$T$113 -> -0.0021720373
A99: 45433 | B99: 98.15 | C99: 97.05 | D99: 111.25 | E99: 109.85 | F99: 102.15 | G99: 101.05 | H99: 99.5 | I99: 98 | K99: =LN(C99/C98) -> 0 | L99: =LN(E99/E98) -> -0.0036347155 | M99: =LN(G99/G98) -> -0.0019772621 | N99: =LN(H99/H98) -> -0.0045124168 | Q99: mean | R99: =AVERAGE(K4:K623) -> 1.5667466e-05 | S99: =AVERAGE(L4:L623) -> -4.5451293e-05 | T99: =AVERAGE(M4:M623) -> -7.974148e-07 | U99: =AVERAGE(N4:N623) -> 8.1383157e-07 | X99: -2.3263479 | AB99: =K100*$S$108+L100*$T$108 -> 0.0035447248 | AC99: =K100*$S$109+M100*$T$109 -> 0.0037472278 | AD99: =K100*$S$110+N100*$T$110 -> 0.0033591744 | AE99: =L100*$S$111+M100*$T$111 -> 0.0037652431 | AF99: =L100*$S$112+N100*$T$112 -> 0.0035870643 | AG99: =M100*$S$113+N100*$T$113 -> 0.0039168783
A100: 45434 | B100: 98.2 | C100: 97.3 | D100: 111.45 | E100: 110.25 | F100: 102.55 | G100: 101.45 | H100: 99.85 | I100: 98.55 | K100: =LN(C100/C99) -> 0.0025726796 | L100: =LN(E100/E99) -> 0.0036347155 | M100: =LN(G100/G99) -> 0.0039506224 | N100: =LN(H100/H99) -> 0.0035114157 | Q100: std.dev | R100: =_xlfn.STDEV.S(K4:K623) -> 0.0016708986 | S100: =_xlfn.STDEV.S(L4:L623) -> 0.0028203583 | T100: =_xlfn.STDEV.S(M4:M623) -> 0.0035981205 | U100: =_xlfn.STDEV.S(N4:N623) -> 0.0028347134 | X100: -1.2815516 | AB100: =K101*$S$108+L101*$T$108 -> 0 | AC100: =K101*$S$109+M101*$T$109 -> 0 | AD100: =K101*$S$110+N101*$T$110 -> 0 | AE100: =L101*$S$111+M101*$T$111 -> 0 | AF100: =L101*$S$112+N101*$T$112 -> 0 | AG100: =M101*$S$113+N101*$T$113 -> 0
A101: 45435 | B101: 98.2 | C101: 97.3 | D101: 111.45 | E101: 110.25 | F101: 102.55 | G101: 101.45 | H101: 99.85 | I101: 98.55 | K101: =LN(C101/C100) -> 0 | L101: =LN(E101/E100) -> 0 | M101: =LN(G101/G100) -> 0 | N101: =LN(H101/H100) -> 0 | Q101: skewness | R101: =_xlfn.SKEW.P(K4:K623) -> -0.61034085 | S101: =_xlfn.SKEW.P(L4:L623) -> -0.039560551 | T101: =_xlfn.SKEW.P(M4:M623) -> -0.55546981 | U101: =_xlfn.SKEW.P(N4:N623) -> -0.15309895 | AB101: =K102*$S$108+L102*$T$108 -> 0 | AC101: =K102*$S$109+M102*$T$109 -> 0 | AD101: =K102*$S$110+N102*$T$110 -> 0 | AE101: =L102*$S$111+M102*$T$111 -> 0 | AF101: =L102*$S$112+N102*$T$112 -> 0 | AG101: =M102*$S$113+N102*$T$113 -> 0
A102: 45436 | B102: 98.2 | C102: 97.3 | D102: 111.45 | E102: 110.25 | F102: 102.55 | G102: 101.45 | H102: 99.85 | I102: 98.55 | K102: =LN(C102/C101) -> 0 | L102: =LN(E102/E101) -> 0 | M102: =LN(G102/G101) -> 0 | N102: =LN(H102/H101) -> 0 | Q102: excess kurtosis | R102: =KURT(K4:K623) -> 6.8739324 | S102: =KURT(L4:L623) -> 3.7618872 | T102: =KURT(M4:M623) -> 6.7063199 | U102: =KURT(N4:N623) -> 12.647214 | AB102: =K103*$S$108+L103*$T$108 -> -4.3553937e-05 | AC102: =K103*$S$109+M103*$T$109 -> -0.0038652245 | AD102: =K103*$S$110+N103*$T$110 -> -0.0051330374 | AE102: =L103*$S$111+M103*$T$111 -> -0.001836829 | AF102: =L103*$S$112+N103*$T$112 -> -0.0023292865 | AG102: =M103*$S$113+N103*$T$113 -> -0.0045670626
A103: 45439 | B103: 98.25 | C103: 97.25 | D103: 111.55 | E103: 110.25 | F103: 102 | G103: 101 | H103: 99.25 | I103: 98.25 | K103: =LN(C103/C102) -> -0.00051400669 | L103: =LN(E103/E102) -> 0 | M103: =LN(G103/G102) -> -0.0044455494 | N103: =LN(H103/H102) -> -0.0060271403 | Q103: Zt | R103: =_xlfn.NORM.INV(0.05,0,1) -> -1.6448536 | S103: =_xlfn.NORM.INV(0.01,0,1) -> -2.3263479 | T103: =_xlfn.NORM.INV(0.1,0,1) -> -1.2815516 | AB103: =K104*$S$108+L104*$T$108 -> -0.00091772489 | AC103: =K104*$S$109+M104*$T$109 -> -0.00015185952 | AD103: =K104*$S$110+N104*$T$110 -> 0.00067688061 | AE103: =L104*$S$111+M104*$T$111 -> -0.00053250112 | AF103: =L104*$S$112+N104*$T$112 -> -0.00016755506 | AG103: =M104*$S$113+N104*$T$113 -> 7.7371309e-05
A104: 45440 | B104: 98.15 | C104: 97.15 | D104: 111.45 | E104: 110.15 | F104: 102 | G104: 101 | H104: 99.35 | I104: 98.25 | K104: =LN(C104/C103) -> -0.0010288067 | L104: =LN(E104/E103) -> -0.00090744108 | M104: =LN(G104/G103) -> 0 | N104: =LN(H104/H103) -> 0.0010070494 | AB104: =K105*$S$108+L105*$T$108 -> -0.0033297565 | AC104: =K105*$S$109+M105*$T$109 -> -0.0012668705 | AD104: =K105*$S$110+N105*$T$110 -> -0.0025337412 | AE104: =L105*$S$111+M105*$T$111 -> -0.0027489453 | AF104: =L105*$S$112+N105*$T$112 -> -0.0034007985 | AG104: =M105*$S$113+N105*$T$113 -> -0.0016044122
A105: 45441 | B105: 98.15 | C105: 97.15 | D105: 111.25 | E105: 109.75 | F105: 101.85 | G105: 100.85 | H105: 99.05 | I105: 97.55 | K105: =LN(C105/C104) -> 0 | L105: =LN(E105/E104) -> -0.0036380213 | M105: =LN(G105/G104) -> -0.0014862524 | N105: =LN(H105/H104) -> -0.0030241959 | AB105: =K106*$S$108+L106*$T$108 -> -0.0039351328 | AC105: =K106*$S$109+M106*$T$109 -> -0.0019962835 | AD105: =K106*$S$110+N106*$T$110 -> -0.0037244985 | AE105: =L106*$S$111+M106*$T$111 -> -0.0032312426 | AF105: =L106*$S$112+N106*$T$112 -> -0.004084651 | AG105: =M106*$S$113+N106*$T$113 -> -0.0021434912
A106: 45442 | B106: 97.95 | C106: 96.95 | D106: 110.9 | E106: 109.3 | F106: 101.65 | G106: 100.65 | H106: 98.65 | I106: 97.15 | K106: =LN(C106/C105) -> -0.0020607941 | L106: =LN(E106/E105) -> -0.0041086568 | M106: =LN(G106/G105) -> -0.0019851123 | N106: =LN(H106/H105) -> -0.0040465407 | Q106: RETURN PORTOFOLIO | AB106: =K107*$S$108+L107*$T$108 -> 0.0053594721 | AC106: =K107*$S$109+M107*$T$109 -> 0.0044102525 | AD106: =K107*$S$110+N107*$T$110 -> 0.0032117383 | AE106: =L107*$S$111+M107*$T$111 -> 0.0050557076 | AF106: =L107*$S$112+N107*$T$112 -> 0.0045322511 | AG106: =M107*$S$113+N107*$T$113 -> 0.0043515274
A107: 45443 | B107: 98.35 | C107: 97.35 | D107: 111.4 | E107: 109.9 | F107: 102.05 | G107: 101.1 | H107: 98.95 | I107: 97.55 | K107: =LN(C107/C106) -> 0.0041173501 | L107: =LN(E107/E106) -> 0.0054744662 | M107: =LN(G107/G106) -> 0.0044609739 | N107: =LN(H107/H106) -> 0.0030364396 | Q107: Obligasi | R107: Dp | S107: w1 | T107: w2 | U107: mean | V107: std.dev | W107: skewness | X107: excess kurtosis | Y107: alpha 5% | Z107: alpha 1% | AA107: alpha 10% | AB107: =K108*$S$108+L108*$T$108 -> 0.00065817768 | AC107: =K108*$S$109+M108*$T$109 -> 0.003062256 | AD107: =K108*$S$110+N108*$T$110 -> 0.0013581922 | AE107: =L108*$S$111+M108*$T$111 -> 0.0021652394 | AF107: =L108*$S$112+N108*$T$112 -> 0.0013383577 | AG107: =M108*$S$113+N108*$T$113 -> 0.0038004303
A108: 45446 | B108: 98.35 | C108: 97.15 | D108: 111.5 | E108: 110 | F108: 102.5 | G108: 101.5 | H108: 99.15 | I108: 98.15 | K108: =LN(C108/C107) -> -0.002056556 | L108: =LN(E108/E107) -> 0.00090950438 | M108: =LN(G108/G107) -> 0.0039486725 | N108: =LN(H108/H107) -> 0.0020191829 | P108: 1 | Q108: ='Simulasi Obligasi'!A48 -> FR0064&FR0072 | R108: ='Simulasi Obligasi'!B48 -> 6 | S108: ='Simulasi Obligasi'!C48 -> 0.084734182 | T108: ='Simulasi Obligasi'!D48 -> 0.91526582 | U108: =AVERAGE(AB3:AB620) -> -4.0207279e-05 | V108: {=TRANSPOSE(AB622:AG622)} -> 0.0026385302 | W108: {=TRANSPOSE(AB623:AG624)} -> -0.023645706 | X108: 3.7026721 | Y108: =X$98 + (1/6)*((X$98^2) - 1)*$W108 + (1/24)*((X$98^3) - 3*X$98)*$X108 - (1/36)*(2*(X$98^3) - 5*X$98)*($W108^2) -> -1.5768419 | Z108: =X$99 + (1/6)*((X$99^2) - 1)*$W108 + (1/24)*((X$99^3) - 3*X$99)*$X108 - (1/36)*(2*(X$99^3) - 5*X$99)*($W108^2) -> -3.2091638 | AA108: =X$100 + (1/6)*((X$100^2) - 1)*$W108 + (1/24)*((X$100^3) - 3*X$100)*$X108 - (1/36)*(2*(X$100^3) - 5*X$100)*($W108^2) -> -1.015694 | AB108: =K109*$S$108+L109*$T$108 -> -0.00024186391 | AC108: =K109*$S$109+M109*$T$109 -> 0.0019815016 | AD108: =K109*$S$110+N109*$T$110 -> 0.00033352586 | AE108: =L109*$S$111+M109*$T$111 -> 0.00054655893 | AF108: =L109*$S$112+N109*$T$112 -> -0.00027894237 | AG108: =M109*$S$113+N109*$T$113 -> 0.001817265
A109: 45447 | B109: 98.35 | C109: 97.35 | D109: 111.55 | E109: 109.95 | F109: 102.55 | G109: 101.7 | H109: 99.15 | I109: 98.15 | K109: =LN(C109/C108) -> 0.002056556 | L109: =LN(E109/E108) -> -0.00045464879 | M109: =LN(G109/G108) -> 0.0019685046 | N109: =LN(H109/H108) -> 0 | P109: 2 | Q109: ='Simulasi Obligasi'!A49 -> FR0064&FR0097 | R109: ='Simulasi Obligasi'!B49 -> 7 | S109: ='Simulasi Obligasi'!C49 -> 0.14760744 | T109: ='Simulasi Obligasi'!D49 -> 0.85239256 | U109: =AVERAGE(AC3:AC620) -> 1.6302819e-06 | V109: 0.0031661927 | W109: -0.53837742 | X109: 6.467741 | Y109: =X$98 + (1/6)*((X$98^2) - 1)*$W109 + (1/24)*((X$98^3) - 3*X$98)*$X109 - (1/36)*(2*(X$98^3) - 5*X$98)*($W109^2) -> -1.6619233 | Z109: =X$99 + (1/6)*((X$99^2) - 1)*$W109 + (1/24)*((X$99^3) - 3*X$99)*$X109 - (1/36)*(2*(X$99^3) - 5*X$99)*($W109^2) -> -4.1252221 | AA109: =X$100 + (1/6)*((X$100^2) - 1)*$W109 + (1/24)*((X$100^3) - 3*X$100)*$X109 - (1/36)*(2*(X$100^3) - 5*X$100)*($W109^2) -> -0.88801455 | AB109: =K110*$S$108+L110*$T$108 -> 0.0012478064 | AC109: =K110*$S$109+M110*$T$109 -> -0.0037800175 | AD109: =K110*$S$110+N110*$T$110 -> -0.0016917181 | AE109: =L110*$S$111+M110*$T$111 -> -0.0010322815 | AF109: =L110*$S$112+N110*$T$112 -> 5.6100822e-05 | AG109: =M110*$S$113+N110*$T$113 -> -0.0042490215
A110: 45448 | B110: 98.35 | C110: 97.35 | D110: 111.1 | E110: 110.1 | F110: 102.35 | G110: 101.25 | H110: 98.95 | I110: 97.75 | K110: =LN(C110/C109) -> 0 | L110: =LN(E110/E109) -> 0.0013633267 | M110: =LN(G110/G109) -> -0.0044345971 | N110: =LN(H110/H109) -> -0.0020191829 | P110: 3 | Q110: ='Simulasi Obligasi'!A50 -> FR0064&FR00102 | R110: ='Simulasi Obligasi'!B50 -> 7 | S110: ='Simulasi Obligasi'!C50 -> 0.16217689 | T110: ='Simulasi Obligasi'!D50 -> 0.83782311 | U110: =AVERAGE(AE3:AE620) -> -2.6957343e-05 | V110: 0.0024574572 | W110: -0.087544949 | X110: 11.505244 | Y110: =X$98 + (1/6)*((X$98^2) - 1)*$W110 + (1/24)*((X$98^3) - 3*X$98)*$X110 - (1/36)*(2*(X$98^3) - 5*X$98)*($W110^2) -> -1.4374106 | Z110: =X$99 + (1/6)*((X$99^2) - 1)*$W110 + (1/24)*((X$99^3) - 3*X$99)*$X110 - (1/36)*(2*(X$99^3) - 5*X$99)*($W110^2) -> -5.0776215 | AA110: =X$100 + (1/6)*((X$100^2) - 1)*$W110 + (1/24)*((X$100^3) - 3*X$100)*$X110 - (1/36)*(2*(X$100^3) - 5*X$100)*($W110^2) -> -0.45732582 | AB110: =K111*$S$108+L111*$T$108 -> -0.00091876735 | AC110: =K111*$S$109+M111*$T$109 -> -0.00099398865 | AD110: =K111*$S$110+N111*$T$110 -> -0.00016667719 | AE110: =L111*$S$111+M111*$T$111 -> -0.00094151135 | AF110: =L111*$S$112+N111*$T$112 -> -0.00055750456 | AG110: =M111*$S$113+N111*$T$113 -> -0.00091222369
A111: 45449 | B111: 98.25 | C111: 97.25 | D111: 111.6 | E111: 110 | F111: 102.15 | G111: 101.15 | H111: 98.95 | I111: 97.75 | K111: =LN(C111/C110) -> -0.0010277493 | L111: =LN(E111/E110) -> -0.00090867794 | M111: =LN(G111/G110) -> -0.00098814237 | N111: =LN(H111/H110) -> 0 | P111: 4 | Q111: ='Simulasi Obligasi'!A51 -> FR0072&FR0097 | R111: ='Simulasi Obligasi'!B51 -> 7 | S111: ='Simulasi Obligasi'!C51 -> 0.5868162 | T111: ='Simulasi Obligasi'!D51 -> 0.4131838 | U111: =AVERAGE(AD3:AD620) -> 3.2175331e-06 | V111: 0.0026992224 | W111: -0.30110985 | X111: 5.6676386 | Y111: =X$98 + (1/6)*((X$98^2) - 1)*$W111 + (1/24)*((X$98^3) - 3*X$98)*$X111 - (1/36)*(2*(X$98^3) - 5*X$98)*($W111^2) -> -1.6143661 | Z111: =X$99 + (1/6)*((X$99^2) - 1)*$W111 + (1/24)*((X$99^3) - 3*X$99)*$X111 - (1/36)*(2*(X$99^3) - 5*X$99)*($W111^2) -> -3.8386616 | AA111: =X$100 + (1/6)*((X$100^2) - 1)*$W111 + (1/24)*((X$100^3) - 3*X$100)*$X111 - (1/36)*(2*(X$100^3) - 5*X$100)*($W111^2) -> -0.90845287 | AB111: =K112*$S$108+L112*$T$108 -> -0.00037257056 | AC111: =K112*$S$109+M112*$T$109 -> 0.00049711785 | AD111: =K112*$S$110+N112*$T$110 -> -0.00034010379 | AE111: =L112*$S$111+M112*$T$111 -> -6.2602633e-05 | AF111: =L112*$S$112+N112*$T$112 -> -0.00047427534 | AG111: =M112*$S$113+N112*$T$113 -> 0.00041739222
A112: 45450 | B112: 98.3 | C112: 97.3 | D112: 111.05 | E112: 109.95 | F112: 102.3 | G112: 101.2 | H112: 98.9 | I112: 97.8 | K112: =LN(C112/C111) -> 0.00051400669 | L112: =LN(E112/E111) -> -0.00045464879 | M112: =LN(G112/G111) -> 0.00049419324 | N112: =LN(H112/H111) -> -0.00050543342 | P112: 5 | Q112: ='Simulasi Obligasi'!A52 -> FR0072&FR00102 | R112: ='Simulasi Obligasi'!B52 -> 7 | S112: ='Simulasi Obligasi'!C52 -> 0.61353372 | T112: ='Simulasi Obligasi'!D52 -> 0.38646628 | U112: =AVERAGE(AF3:AF620) -> -2.7526769e-05 | V112: 0.0023425278 | W112: -0.39118859 | X112: 4.4155491 | Y112: =X$98 + (1/6)*((X$98^2) - 1)*$W112 + (1/24)*((X$98^3) - 3*X$98)*$X112 - (1/36)*(2*(X$98^3) - 5*X$98)*($W112^2) -> -1.6640684 | Z112: =X$99 + (1/6)*((X$99^2) - 1)*$W112 + (1/24)*((X$99^3) - 3*X$99)*$X112 - (1/36)*(2*(X$99^3) - 5*X$99)*($W112^2) -> -3.5887058 | AA112: =X$100 + (1/6)*((X$100^2) - 1)*$W112 + (1/24)*((X$100^3) - 3*X$100)*$X112 - (1/36)*(2*(X$100^3) - 5*X$100)*($W112^2) -> -1.0126743 | AB112: =K113*$S$108+L113*$T$108 -> -0.0017535228 | AC112: =K113*$S$109+M113*$T$109 -> -0.0060682632 | AD112: =K113*$S$110+N113*$T$110 -> -0.00016676289 | AE112: =L113*$S$111+M113*$T$111 -> -0.0039363166 | AF112: =L113*$S$112+N113*$T$112 -> -0.0011170394 | AG112: =M113*$S$113+N113*$T$113 -> -0.0064077521
A113: 45453 | B113: 98.1 | C113: 97.2 | D113: 110.95 | E113: 109.75 | F113: 101.5 | G113: 100.5 | H113: 98.9 | I113: 97.7 | K113: =LN(C113/C112) -> -0.0010282777 | L113: =LN(E113/E112) -> -0.001820665 | M113: =LN(G113/G112) -> -0.0069410294 | N113: =LN(H113/H112) -> 0 | P113: 6 | Q113: ='Simulasi Obligasi'!A53 -> FR0097&FR00102 | R113: ='Simulasi Obligasi'!B53 -> 7.89 | S113: ='Simulasi Obligasi'!C53 -> 0.9231703 | T113: ='Simulasi Obligasi'!D53 -> 0.076829703 | U113: =AVERAGE(AG3:AG620) -> -6.7253321e-07 | V113: 0.0034230911 | W113: -0.54379572 | X113: 6.6176663 | Y113: =X$98 + (1/6)*((X$98^2) - 1)*$W113 + (1/24)*((X$98^3) - 3*X$98)*$X113 - (1/36)*(2*(X$98^3) - 5*X$98)*($W113^2) -> -1.6603277 | Z113: =X$99 + (1/6)*((X$99^2) - 1)*$W113 + (1/24)*((X$99^3) - 3*X$99)*$X113 - (1/36)*(2*(X$99^3) - 5*X$99)*($W113^2) -> -4.1620503 | AA113: =X$100 + (1/6)*((X$100^2) - 1)*$W113 + (1/24)*((X$100^3) - 3*X$100)*$X113 - (1/36)*(2*(X$100^3) - 5*X$100)*($W113^2) -> -0.87808393 | AB113: =K114*$S$108+L114*$T$108 -> -0.0050174588 | AC113: =K114*$S$109+M114*$T$109 -> -0.0038252535 | AD113: =K114*$S$110+N114*$T$110 -> -0.0068046921 | AE113: =L114*$S$111+M114*$T$111 -> -0.0050711393 | AF113: =L114*$S$112+N114*$T$112 -> -0.0065022025 | AG113: =M114*$S$113+N114*$T$113 -> -0.0047668814
A114: 45454 | B114: 98.1 | C114: 97.2 | D114: 110.45 | E114: 109.15 | F114: 101.15 | G114: 100.05 | H114: 98.1 | I114: 97.1 | K114: =LN(C114/C113) -> 0 | L114: =LN(E114/E113) -> -0.005481969 | M114: =LN(G114/G113) -> -0.0044876665 | N114: =LN(H114/H113) -> -0.0081218721 | AB114: =K115*$S$108+L115*$T$108 -> -0.00024519475 | AC114: =K115*$S$109+M115*$T$109 -> 0.0011549481 | AD114: =K115*$S$110+N115*$T$110 -> 0.0020397158 | AE114: =L115*$S$111+M115*$T$111 -> 0.00014389766 | AF114: =L115*$S$112+N115*$T$112 -> 0.00050598552 | AG114: =M115*$S$113+N115*$T$113 -> 0.0010787242
A115: 45455 | B115: 98.2 | C115: 97.4 | D115: 110.1 | E115: 109.1 | F115: 101.15 | G115: 100.15 | H115: 98.3 | I115: 97.3 | K115: =LN(C115/C114) -> 0.0020554992 | L115: =LN(E115/E114) -> -0.00045819016 | M115: =LN(G115/G114) -> 0.00099900108 | N115: =LN(H115/H114) -> 0.0020366606 | AB115: =K116*$S$108+L116*$T$108 -> 0.00037585658 | AC115: =K116*$S$109+M116*$T$109 -> -0.0005014575 | AD115: =K116*$S$110+N116*$T$110 -> 0.00034277346 | AE115: =L116*$S$111+M116*$T$111 -> 6.2539418e-05 | AF115: =L116*$S$112+N116*$T$112 -> 0.00047764005 | AG115: =M116*$S$113+N116*$T$113 -> -0.00042193963
A116: 45456 | B116: 98.35 | C116: 97.35 | D116: 110.15 | E116: 109.15 | F116: 101.1 | G116: 100.1 | H116: 98.35 | I116: 97.25 | K116: =LN(C116/C115) -> -0.00051347883 | L116: =LN(E116/E115) -> 0.00045819016 | M116: =LN(G116/G115) -> -0.00049937579 | N116: =LN(H116/H115) -> 0.00050851768 | Q116: VaR | R116: 0.01 | S116: 0.05 | T116: 0.1 | AB116: =K117*$S$108+L117*$T$108 -> -0.0041473293 | AC116: =K117*$S$109+M117*$T$109 -> -0.0069240424 | AD116: =K117*$S$110+N117*$T$110 -> -0.0023586102 | AE116: =L117*$S$111+M117*$T$111 -> -0.0048462053 | AF116: =L117*$S$112+N117*$T$112 -> -0.0026456856 | AG116: =M117*$S$113+N117*$T$113 -> -0.0060923184
A117: 45457 | B117: 98.05 | C117: 96.45 | D117: 109.75 | E117: 108.75 | F117: 100.45 | G117: 99.45 | H117: 98.25 | I117: 96.95 | K117: =LN(C117/C116) -> -0.0092879925 | L117: =LN(E117/E116) -> -0.003671413 | M117: =LN(G117/G116) -> -0.006514681 | N117: =LN(H117/H116) -> -0.0010172941 | Q117: =Q108 -> FR0064&FR0072 | R117: =(VaR!U108-VaR!Z108*VaR!V108) -> 0.0084272684 | S117: =(U108-Y108*V108) -> 0.0041203377 | T117: =(U108-AA108*V108) -> 0.0026397321 | AB117: =K118*$S$108+L118*$T$108 -> 0 | AC117: =K118*$S$109+M118*$T$109 -> 0 | AD117: =K118*$S$110+N118*$T$110 -> 0 | AE117: =L118*$S$111+M118*$T$111 -> 0 | AF117: =L118*$S$112+N118*$T$112 -> 0 | AG117: =M118*$S$113+N118*$T$113 -> 0
A118: 45460 | B118: 98.05 | C118: 96.45 | D118: 109.75 | E118: 108.75 | F118: 100.45 | G118: 99.45 | H118: 98.25 | I118: 96.95 | K118: =LN(C118/C117) -> 0 | L118: =LN(E118/E117) -> 0 | M118: =LN(G118/G117) -> 0 | N118: =LN(H118/H117) -> 0 | Q118: =Q109 -> FR0064&FR0097 | R118: =(VaR!U109-VaR!Z109*VaR!V109) -> 0.013062879 | S118: =(U109-Y109*V109) -> 0.0052635998 | T118: =(U109-AA109*V109) -> 0.0028132555 | AB118: =K119*$S$108+L119*$T$108 -> 0 | AC118: =K119*$S$109+M119*$T$109 -> 0 | AD118: =K119*$S$110+N119*$T$110 -> 0 | AE118: =L119*$S$111+M119*$T$111 -> 0 | AF118: =L119*$S$112+N119*$T$112 -> 0 | AG118: =M119*$S$113+N119*$T$113 -> 0
A119: 45461 | B119: 98.05 | C119: 96.45 | D119: 109.75 | E119: 108.75 | F119: 100.45 | G119: 99.45 | H119: 98.25 | I119: 96.95 | K119: =LN(C119/C118) -> 0 | L119: =LN(E119/E118) -> 0 | M119: =LN(G119/G118) -> 0 | N119: =LN(H119/H118) -> 0 | Q119: =Q110 -> FR0064&FR00102 | R119: =(VaR!U110-VaR!Z110*VaR!V110) -> 0.01245108 | S119: =(U110-Y110*V110) -> 0.0035054176 | T119: =(U110-AA110*V110) -> 0.0010969013 | AB119: =K120*$S$108+L120*$T$108 -> -0.0030657726 | AC119: =K120*$S$109+M120*$T$109 -> 0.00096311741 | AD119: =K120*$S$110+N120*$T$110 -> -0.007122637 | AE119: =L120*$S$111+M120*$T$111 -> -0.0019547014 | AF119: =L120*$S$112+N120*$T$112 -> -0.0058172994 | AG119: =M120*$S$113+N120*$T$113 -> -0.00024300553
A120: 45462 | B120: 97.8 | C120: 96.8 | D120: 109.35 | E120: 108.35 | F120: 100.5 | G120: 99.5 | H120: 97.35 | I120: 96.35 | K120: =LN(C120/C119) -> 0.0036222549 | L120: =LN(E120/E119) -> -0.003684942 | M120: =LN(G120/G119) -> 0.00050263886 | N120: =LN(H120/H119) -> -0.0092025189 | Q120: =Q111 -> FR0072&FR0097 | R120: =(VaR!U111-VaR!Z111*VaR!V111) -> 0.010364619 | S120: =(U111-Y111*V111) -> 0.0043607507 | T120: =(U111-AA111*V111) -> 0.0024553338 | AB120: =K121*$S$108+L121*$T$108 -> 0.00071293641 | AC120: =K121*$S$109+M121*$T$109 -> -0.00022890794 | AD120: =K121*$S$110+N121*$T$110 -> 0.0010384491 | AE120: =L121*$S$111+M121*$T$111 -> 0.00054134339 | AF120: =L121*$S$112+N121*$T$112 -> 0.0011610119 | AG120: =M121*$S$113+N121*$T$113 -> 0.00011829056
A121: 45463 | B121: 97.75 | C121: 96.65 | D121: 109.95 | E121: 108.45 | F121: 100.6 | G121: 99.5 | H121: 97.5 | I121: 96.4 | K121: =LN(C121/C120) -> -0.0015507886 | L121: =LN(E121/E120) -> 0.00092250929 | M121: =LN(G121/G120) -> 0 | N121: =LN(H121/H120) -> 0.0015396462 | Q121: =Q112 -> FR0072&FR00102 | R121: =(VaR!U112-VaR!Z112*VaR!V112) -> 0.0083791163 | S121: =(U112-Y112*V112) -> 0.0038705998 | T121: =(U112-AA112*V112) -> 0.0023446909 | AB121: =K122*$S$108+L122*$T$108 -> 0.001571348 | AC121: =K122*$S$109+M122*$T$109 -> -0.0029000427 | AD121: =K122*$S$110+N122*$T$110 -> -0.0024267487 | AE121: =L122*$S$111+M122*$T$111 -> -0.00085330828 | AF121: =L122*$S$112+N122*$T$112 -> -0.00054180282 | AG121: =M122*$S$113+N122*$T$113 -> -0.0039950123
...

Sheet Korelasi
B1: FR0064 | C1: FR0072 | D1: FR0097 | E1: FR00102
A2: FR0064 | B2: 1
A3: FR0072 | B3: 0.39483179 | C3: 1
A4: FR0097 | B4: 0.37912712 | C4: 0.4772089 | D4: 1
A5: FR00102 | B5: 0.2576459 | C5: 0.34139518 | D5: 0.45351329 | E5: 1

Sheet Backtesting
A10: Total hari | C10: =COUNT(VaR!AB3:AB620) -> 618 | D10: alpha | E10: 0.05
A11: Obligasi | B11: Total hari | C11: n (violation) | D11: Pembilang | E11: Penyebut | F11: LR | G11: Status
A12: FR0064&FR0072 | B12: 618 | C12: =COUNTIF(VaR!AB3:AB620, ">" & VaR!S117) -> 29 | D12: =((1 - $E$10)^($C$10 - C12)) * ($E$10^C12) -> 1.4103719e-51 | E12: =((1 - (C12 / $C$10))^($C$10 - C12)) * ((C12 / $C$10)^C12) -> 1.5016647e-51 | F12: =-2*LN(D12/E12) -> 0.12544172 | G12: =IF( F12< 3.84, "Model Akurat (Diterima)", "Model Gagal (Ditolak)") -> Model Akurat (Diterima)
A13: FR0064&FR0097 | B13: 618 | C13: =COUNTIF(VaR!AC3:AC620, ">" & VaR!S118) -> 28 | D13: =((1 - $E$10)^($C$10 - C13)) * ($E$10^C13) -> 2.6797066e-50 | E13: =((1 - (C13 / $C$10))^($C$10 - C13)) * ((C13 / $C$10)^C13) -> 3.1062338e-50 | F13: =-2*LN(D13/E13) -> 0.29540739 | G13: =IF( F13< 3.84, "Model Akurat (Diterima)", "Model Gagal (Ditolak)") -> Model Akurat (Diterima)
A14: FR0064&FR00102 | B14: 618 | C14: =COUNTIF(VaR!AD3:AD620, ">" & VaR!S119) -> 26 | D14: =((1 - $E$10)^($C$10 - C14)) * ($E$10^C14) -> 9.6737407e-48 | E14: =((1 - (C14 / $C$10))^($C$10 - C14)) * ((C14 / $C$10)^C14) -> 1.488949e-47 | F14: =-2*LN(D14/E14) -> 0.86248104 | G14: =IF( F14< 3.84, "Model Akurat (Diterima)", "Model Gagal (Ditolak)") -> Model Akurat (Diterima)
A15: FR0072&FR0097 | B15: 618 | C15: =COUNTIF(VaR!AE3:AE620, ">" & VaR!S120) -> 24 | D15: =((1 - $E$10)^($C$10 - C15)) * ($E$10^C15) -> 3.4922204e-45 | E15: =((1 - (C15 / $C$10))^($C$10 - C15)) * ((C15 / $C$10)^C15) -> 8.3818622e-45 | F15: =-2*LN(D15/E15) -> 1.7510647 | G15: =IF( F15< 3.84, "Model Akurat (Diterima)", "Model Gagal (Ditolak)") -> Model Akurat (Diterima)
A16: FR0072&FR00102 | B16: 618 | C16: =COUNTIF(VaR!AF3:AF620, ">" & VaR!S121) -> 23 | D16: =((1 - $E$10)^($C$10 - C16)) * ($E$10^C16) -> 6.6352188e-44 | E16: =((1 - (C16 / $C$10))^($C$10 - C16)) * ((C16 / $C$10)^C16) -> 2.1205926e-43 | F16: =-2*LN(D16/E16) -> 2.323778 | G16: =IF( F16< 3.84, "Model Akurat (Diterima)", "Model Gagal (Ditolak)") -> Model Akurat (Diterima)
A17: FR0097&FR00102 | B17: 618 | C17: =COUNTIF(VaR!AG3:AG620, ">" & VaR!S122) -> 25 | D17: =((1 - $E$10)^($C$10 - C17)) * ($E$10^C17) -> 1.8380107e-46 | E17: =((1 - (C17 / $C$10))^($C$10 - C17)) * ((C17 / $C$10)^C17) -> 3.4598381e-46 | F17: =-2*LN(D17/E17) -> 1.2650759 | G17: =IF( F17< 3.84, "Model Akurat (Diterima)", "Model Gagal (Ditolak)") -> Model Akurat (Diterima)

Sheet Simulasi Obligasi (Opsi)
A1: Obligasi | B1: FR0100 | C1: FR0072 | D1: FR0097 | E1: FR00102
A2: Coupon | B2: 0.06625 | C2: 0.0825 | D2: 0.07125 | E2: 0.07375
A3: Periode Pemberian | B3: 2 | C3: 2 | D3: 2 | E3: 2
A4: Yield Bid | B4: 0.0711 | C4: 0.0697 | D4: 0.0697 | E4: 0.0706
A5: Harga Beli | B5: 0.995 | C5: 1.091 | D5: 1.021 | E5: 0.9775
A6: Dikeluarkan | B6: 45162 | C6: 42194 | D6: 44792 | E6: 45296
A7: Jatuh Tempo | B7: 48990 | C7: 49810 | D7: 52397 | E7: 56445
A8: Harga (FV) | B8: 1000000 | C8: 1000000 | D8: 1000000 | E8: 1000000
A9: Sisa Tenor | B9: 7.7 | C9: 10 | D9: 17.1 | E9: 28.2
A10: Harga (PV) | B10: =B8*B5 -> 995000 | C10: =C8*C5 -> 1091000 | D10: 1021000 | E10: 977500
A11: YTM | B11: 0.0671 | C11: 0.0679 | D11: 0.0691 | E11: 0.0692
A14: FR00100 | G14: FR0072 | M14: FR0097 | S14: FR00102
A15: Kupon p.a | B15: =B2*B8 -> 66250 | G15: Kupon p.a | H15: =C8*C2 -> 82500 | M15: Kupon p.a | N15: =D2*D8 -> 71250 | S15: Kupon p.a | T15: =E2*E8 -> 73750
A16: Kupon tiap periode | B16: =B15/2 -> 33125 | G16: Kupon tiap periode | H16: =H15/2 -> 41250 | M16: Kupon tiap periode | N16: =N15/2 -> 35625 | S16: Kupon tiap periode | T16: =T15/2 -> 36875
A17: YTM periode | B17: =B11/2 -> 0.03355 | G17: YTM periode | H17: =C11/2 -> 0.03395 | M17: YTM periode | N17: =D11/2 -> 0.03455 | S17: YTM periode | T17: =E11/2 -> 0.0346
A18: Sisa periode | B18: =B9 -> 7.7 | G18: Sisa periode | H18: =C9 -> 10 | M18: Sisa periode | N18: =D9 -> 17.1 | S18: Sisa periode | T18: =E9 -> 28.2
A19: Jumlah Pembayaran | B19: =B18*2 -> 15.4 | G19: Jumlah Pembayaran | H19: =H18*2 -> 20 | M19: Jumlah Pembayaran | N19: =N18*2 -> 34.2 | S19: Jumlah Pembayaran | T19: =T18*2 -> 56.4
A22: Periode (t) | B22: Cash Flow | C22: PV | D22: Total | G22: Periode (t) | H22: Cash Flow | I22: PV | J22: Total | M22: Periode (t) | N22: Cash Flow | O22: PV | P22: Total | S22: Periode (t) | T22: Cash Flow | U22: PV | V22: Total
A23: 1 | B23: =$B$16 -> 33125 | C23: =B23/((1+$B$17)^A23) -> 32049.732 | D23: =A23*C23 -> 32049.732 | G23: 1 | H23: =$H$16 -> 41250 | I23: =H23/(1+$H$17)^G23 -> 39895.546 | J23: =G23*I23 -> 39895.546 | M23: 1 | N23: =N16 -> 35625 | O23: =N23/(1+$N$17)^M23 -> 34435.262 | P23: =O23*M23 -> 34435.262 | S23: 1 | T23: =T16 -> 36875 | U23: =T23/(1+$T$17)^S23 -> 35641.794 | V23: =U23*S23 -> 35641.794
A24: 2 | B24: =$B$16 -> 33125 | C24: =B24/((1+$B$17)^A24) -> 31009.367 | D24: =A24*C24 -> 62018.734 | G24: 2 | H24: =$H$16 -> 41250 | I24: =H24/(1+$H$17)^G24 -> 38585.566 | J24: =G24*I24 -> 77171.132 | M24: 2 | N24: =$N$23 -> 35625 | O24: =N24/(1+$N$17)^M24 -> 33285.256 | P24: =O24*M24 -> 66570.512 | S24: 2 | T24: =$T$23 -> 36875 | U24: =T24/(1+$T$17)^S24 -> 34449.83 | V24: =U24*S24 -> 68899.66
A25: 3 | B25: =$B$16 -> 33125 | C25: =B25/((1+$B$17)^A25) -> 30002.774 | D25: =A25*C25 -> 90008.322 | G25: 3 | H25: =$H$16 -> 41250 | I25: =H25/(1+$H$17)^G25 -> 37318.6 | J25: =G25*I25 -> 111955.8 | M25: 3 | N25: =$N$23 -> 35625 | O25: =N25/(1+$N$17)^M25 -> 32173.656 | P25: =O25*M25 -> 96520.969 | S25: 3 | T25: =$T$23 -> 36875 | U25: =T25/(1+$T$17)^S25 -> 33297.728 | V25: =U25*S25 -> 99893.185
A26: 4 | B26: =$B$16 -> 33125 | C26: =B26/((1+$B$17)^A26) -> 29028.856 | D26: =A26*C26 -> 116115.42 | G26: 4 | H26: =$H$16 -> 41250 | I26: =H26/(1+$H$17)^G26 -> 36093.234 | J26: =G26*I26 -> 144372.94 | M26: 4 | N26: =$N$23 -> 35625 | O26: =N26/(1+$N$17)^M26 -> 31099.18 | P26: =O26*M26 -> 124396.72 | S26: 4 | T26: =$T$23 -> 36875 | U26: =T26/(1+$T$17)^S26 -> 32184.157 | V26: =U26*S26 -> 128736.63
A27: 5 | B27: =$B$16 -> 33125 | C27: =B27/((1+$B$17)^A27) -> 28086.552 | D27: =A27*C27 -> 140432.76 | G27: 5 | H27: =$H$16 -> 41250 | I27: =H27/(1+$H$17)^G27 -> 34908.104 | J27: =G27*I27 -> 174540.52 | M27: 5 | N27: =$N$23 -> 35625 | O27: =N27/(1+$N$17)^M27 -> 30060.586 | P27: =O27*M27 -> 150302.93 | S27: 5 | T27: =$T$23 -> 36875 | U27: =T27/(1+$T$17)^S27 -> 31107.826 | V27: =U27*S27 -> 155539.13
A28: 6 | B28: =$B$16 -> 33125 | C28: =B28/((1+$B$17)^A28) -> 27174.836 | D28: =A28*C28 -> 163049.02 | G28: 6 | H28: =$H$16 -> 41250 | I28: =H28/(1+$H$17)^G28 -> 33761.888 | J28: =G28*I28 -> 202571.33 | M28: 6 | N28: =$N$23 -> 35625 | O28: =N28/(1+$N$17)^M28 -> 29056.678 | P28: =O28*M28 -> 174340.07 | S28: 6 | T28: =$T$23 -> 36875 | U28: =T28/(1+$T$17)^S28 -> 30067.491 | V28: =U28*S28 -> 180404.94
A29: 7 | B29: =$B$16 -> 33125 | C29: =B29/((1+$B$17)^A29) -> 26292.716 | D29: =A29*C29 -> 184049.01 | G29: 7 | H29: =$H$16 -> 41250 | I29: =H29/(1+$H$17)^G29 -> 32653.308 | J29: =G29*I29 -> 228573.16 | M29: 7 | N29: =$N$23 -> 35625 | O29: =N29/(1+$N$17)^M29 -> 28086.297 | P29: =O29*M29 -> 196604.08 | S29: 7 | T29: =$T$23 -> 36875 | U29: =T29/(1+$T$17)^S29 -> 29061.947 | V29: =U29*S29 -> 203433.63
A30: 8 | B30: =$B$16 -> 33125 | C30: =B30/((1+$B$17)^A30) -> 25439.23 | D30: =A30*C30 -> 203513.84 | G30: 8 | H30: =$H$16 -> 41250 | I30: =H30/(1+$H$17)^G30 -> 31581.129 | J30: =G30*I30 -> 252649.03 | M30: 8 | N30: =$N$23 -> 35625 | O30: =N30/(1+$N$17)^M30 -> 27148.322 | P30: =O30*M30 -> 217186.58 | S30: 8 | T30: =$T$23 -> 36875 | U30: =T30/(1+$T$17)^S30 -> 28090.032 | V30: =U30*S30 -> 224720.26
A31: 9 | B31: =$B$16 -> 33125 | C31: =B31/((1+$B$17)^A31) -> 24613.448 | D31: =A31*C31 -> 221521.04 | G31: 9 | H31: =$H$16 -> 41250 | I31: =H31/(1+$H$17)^G31 -> 30544.155 | J31: =G31*I31 -> 274897.4 | M31: 9 | N31: =$N$23 -> 35625 | O31: =N31/(1+$N$17)^M31 -> 26241.672 | P31: =O31*M31 -> 236175.05 | S31: 9 | T31: =$T$23 -> 36875 | U31: =T31/(1+$T$17)^S31 -> 27150.621 | V31: =U31*S31 -> 244355.59
A32: 10 | B32: =$B$16 -> 33125 | C32: =B32/((1+$B$17)^A32) -> 23814.473 | D32: =A32*C32 -> 238144.73 | G32: 10 | H32: =$H$16 -> 41250 | I32: =H32/(1+$H$17)^G32 -> 29541.23 | J32: =G32*I32 -> 295412.3 | M32: 10 | N32: =$N$23 -> 35625 | O32: =N32/(1+$N$17)^M32 -> 25365.301 | P32: =O32*M32 -> 253653.01 | S32: 10 | T32: =$T$23 -> 36875 | U32: =T32/(1+$T$17)^S32 -> 26242.626 | V32: =U32*S32 -> 262426.26
A33: 11 | B33: =$B$16 -> 33125 | C33: =B33/((1+$B$17)^A33) -> 23041.433 | D33: =A33*C33 -> 253455.76 | G33: 11 | H33: =$H$16 -> 41250 | I33: =H33/(1+$H$17)^G33 -> 28571.237 | J33: =G33*I33 -> 314283.6 | M33: 11 | N33: =$N$23 -> 35625 | O33: =N33/(1+$N$17)^M33 -> 24518.197 | P33: =O33*M33 -> 269700.17 | S33: 11 | T33: =$T$23 -> 36875 | U33: =T33/(1+$T$17)^S33 -> 25364.997 | V33: =U33*S33 -> 279014.97
A34: 12 | B34: =$B$16 -> 33125 | C34: =B34/((1+$B$17)^A34) -> 22293.486 | D34: =A34*C34 -> 267521.84 | G34: 12 | H34: =$H$16 -> 41250 | I34: =H34/(1+$H$17)^G34 -> 27633.093 | J34: =G34*I34 -> 331597.12 | M34: 12 | N34: =$N$23 -> 35625 | O34: =N34/(1+$N$17)^M34 -> 23699.384 | P34: =O34*M34 -> 284392.6 | S34: 12 | T34: =$T$23 -> 36875 | U34: =T34/(1+$T$17)^S34 -> 24516.718 | V34: =U34*S34 -> 294200.62
A35: 13 | B35: =$B$16 -> 33125 | C35: =B35/((1+$B$17)^A35) -> 21569.819 | D35: =A35*C35 -> 280407.65 | G35: 13 | H35: =$H$16 -> 41250 | I35: =H35/(1+$H$17)^G35 -> 26725.754 | J35: =G35*I35 -> 347434.8 | M35: 13 | N35: =$N$23 -> 35625 | O35: =N35/(1+$N$17)^M35 -> 22907.915 | P35: =O35*M35 -> 297802.9 | S35: 13 | T35: =$T$23 -> 36875 | U35: =T35/(1+$T$17)^S35 -> 23696.809 | V35: =U35*S35 -> 308058.52
... A37: 15 | B37: =$B$16 -> 33125 | C37: =B37/((1+$B$17)^A37) -> 20192.194 | D37: =A37*C37 -> 302882.91 | G37: 15 | H37: =$H$16 -> 41250 | I37: =H37/(1+$H$17)^G37 -> 24999.475 | J37: =G37*I37 -> 374992.13 | M37: 15 | N37: =$N$23 -> 35625 | O37: =N37/(1+$N$17)^M37 -> 21403.392 | P37: =O37*M37 -> 321050.87 | S37: 15 | T37: =$T$23 -> 36875 | U37: =T37/(1+$T$17)^S37 -> 22138.333 | V37: =U37*S37 -> 332075
A38: 15.4 | B38: =$B$16+B8 -> 1033125 | C38: =B38/((1+$B$17)^A38) -> 621509.69 | D38: =A38*C38 -> 9571249.2 | G38: 16 | H38: =$H$16 -> 41250 | I38: =H38/(1+$H$17)^G38 -> 24178.611 | J38: =G38*I38 -> 386857.78 | M38: 16 | N38: =$N$23 -> 35625 | O38: =N38/(1+$N$17)^M38 -> 20688.6 | P38: =O38*M38 -> 331017.61 | S38: 16 | T38: =$T$23 -> 36875 | U38: =T38/(1+$T$17)^S38 -> 21397.964 | V38: =U38*S38 -> 342367.42
C39: =SUM(C23:C38) -> 1006988.3 | D39: =SUM(D23:D38) -> 12418595 | G39: 17 | H39: =$H$16 -> 41250 | I39: =H39/(1+$H$17)^G39 -> 23384.701 | J39: =G39*I39 -> 397539.91 | M39: 17 | N39: =$N$23 -> 35625 | O39: =N39/(1+$N$17)^M39 -> 19997.681 | P39: =O39*M39 -> 339960.57 | S39: 17 | T39: =$T$23 -> 36875 | U39: =T39/(1+$T$17)^S39 -> 20682.354 | V39: =U39*S39 -> 351600.02
C40: Durasi | D40: =D39/C39 -> 12.332413 | G40: 18 | H40: =$H$16 -> 41250 | I40: =H40/(1+$H$17)^G40 -> 22616.858 | J40: =G40*I40 -> 407103.45 | M40: 18 | N40: =$N$23 -> 35625 | O40: =N40/(1+$N$17)^M40 -> 19329.835 | P40: =O40*M40 -> 347937.03 | S40: 18 | T40: =$T$23 -> 36875 | U40: =T40/(1+$T$17)^S40 -> 19990.677 | V40: =U40*S40 -> 359832.18
D41: =D40/2 -> 6.1662065 | G41: 19 | H41: =$H$16 -> 41250 | I41: =H41/(1+$H$17)^G41 -> 21874.228 | J41: =G41*I41 -> 415610.34 | M41: 19 | N41: =$N$23 -> 35625 | O41: =N41/(1+$N$17)^M41 -> 18684.292 | P41: =O41*M41 -> 355001.56 | S41: 19 | T41: =$T$23 -> 36875 | U41: =T41/(1+$T$17)^S41 -> 19322.131 | V41: =U41*S41 -> 367120.49
D42: =1+(B11/B3) -> 1.03355 | G42: 20 | H42: =$H$16+C8 -> 1041250 | I42: =H42/(1+$H$17)^G42 -> 534028.29 | J42: =G42*I42 -> 10680566 | M42: 20 | N42: =$N$23 -> 35625 | O42: =N42/(1+$N$17)^M42 -> 18060.309 | P42: =O42*M42 -> 361206.18 | S42: 20 | T42: =$T$23 -> 36875 | U42: =T42/(1+$T$17)^S42 -> 18675.943 | V42: =U42*S42 -> 373518.87
D43: =D41/D42 -> 5.9660457 | I43: =SUM(I23:I42) -> 1104743.2 | J43: =SUM(J23:J42) -> 15819899 | M43: 21 | N43: =$N$23 -> 35625 | O43: =N43/(1+$N$17)^M43 -> 17457.164 | P43: =O43*M43 -> 366600.44 | S43: 21 | T43: =$T$23 -> 36875 | U43: =T43/(1+$T$17)^S43 -> 18051.366 | V43: =U43*S43 -> 379078.69
I44: Durasi | J44: =J43/I43 -> 14.319978 | M44: 22 | N44: =$N$23 -> 35625 | O44: =N44/(1+$N$17)^M44 -> 16874.162 | P44: =O44*M44 -> 371231.55 | S44: 22 | T44: =$T$23 -> 36875 | U44: =T44/(1+$T$17)^S44 -> 17447.676 | V44: =U44*S44 -> 383848.88
A45: Pembobotan | J45: =J44/2 -> 7.1599892 | M45: 23 | N45: =$N$23 -> 35625 | O45: =N45/(1+$N$17)^M45 -> 16310.629 | P45: =O45*M45 -> 375144.47 | S45: 23 | T45: =$T$23 -> 36875 | U45: =T45/(1+$T$17)^S45 -> 16864.176 | V45: =U45*S45 -> 387876.05
...
